[2022-10-01 20:12:48,680] {taskinstance.py:1159} INFO - Dependencies all met for <TaskInstance: main_dag.web_scraping manual__2022-10-01T20:12:44.062201+00:00 [queued]>
[2022-10-01 20:12:48,695] {taskinstance.py:1159} INFO - Dependencies all met for <TaskInstance: main_dag.web_scraping manual__2022-10-01T20:12:44.062201+00:00 [queued]>
[2022-10-01 20:12:48,695] {taskinstance.py:1356} INFO - 
--------------------------------------------------------------------------------
[2022-10-01 20:12:48,696] {taskinstance.py:1357} INFO - Starting attempt 1 of 1
[2022-10-01 20:12:48,696] {taskinstance.py:1358} INFO - 
--------------------------------------------------------------------------------
[2022-10-01 20:12:48,765] {taskinstance.py:1377} INFO - Executing <Task(PythonOperator): web_scraping> on 2022-10-01 20:12:44.062201+00:00
[2022-10-01 20:12:53,843] {standard_task_runner.py:52} INFO - Started process 1356 to run task
[2022-10-01 20:12:53,870] {standard_task_runner.py:79} INFO - Running: ['***', 'tasks', 'run', 'main_dag', 'web_scraping', 'manual__2022-10-01T20:12:44.062201+00:00', '--job-id', '77', '--raw', '--subdir', 'DAGS_FOLDER/main_dag.py', '--cfg-path', '/tmp/tmprqy72rsa', '--error-file', '/tmp/tmp243f23bn']
[2022-10-01 20:12:53,886] {standard_task_runner.py:80} INFO - Job 77: Subtask web_scraping
[2022-10-01 20:12:54,593] {task_command.py:369} INFO - Running <TaskInstance: main_dag.web_scraping manual__2022-10-01T20:12:44.062201+00:00 [running]> on host cb37a969dddb
[2022-10-01 20:12:55,830] {taskinstance.py:1571} INFO - Exporting the following env vars:
AIRFLOW_CTX_DAG_OWNER=***
AIRFLOW_CTX_DAG_ID=main_dag
AIRFLOW_CTX_TASK_ID=web_scraping
AIRFLOW_CTX_EXECUTION_DATE=2022-10-01T20:12:44.062201+00:00
AIRFLOW_CTX_TRY_NUMBER=1
AIRFLOW_CTX_DAG_RUN_ID=manual__2022-10-01T20:12:44.062201+00:00
[2022-10-01 20:13:14,618] {taskinstance.py:1889} ERROR - Task failed with exception
Traceback (most recent call last):
  File "/home/airflow/.local/lib/python3.7/site-packages/urllib3/connection.py", line 175, in _new_conn
    (self._dns_host, self.port), self.timeout, **extra_kw
  File "/home/airflow/.local/lib/python3.7/site-packages/urllib3/util/connection.py", line 72, in create_connection
    for res in socket.getaddrinfo(host, port, family, socket.SOCK_STREAM):
  File "/usr/local/lib/python3.7/socket.py", line 752, in getaddrinfo
    for res in _socket.getaddrinfo(host, port, family, type, proto, flags):
socket.gaierror: [Errno -3] Temporary failure in name resolution

During handling of the above exception, another exception occurred:

Traceback (most recent call last):
  File "/home/airflow/.local/lib/python3.7/site-packages/urllib3/connectionpool.py", line 710, in urlopen
    chunked=chunked,
  File "/home/airflow/.local/lib/python3.7/site-packages/urllib3/connectionpool.py", line 386, in _make_request
    self._validate_conn(conn)
  File "/home/airflow/.local/lib/python3.7/site-packages/urllib3/connectionpool.py", line 1040, in _validate_conn
    conn.connect()
  File "/home/airflow/.local/lib/python3.7/site-packages/urllib3/connection.py", line 358, in connect
    self.sock = conn = self._new_conn()
  File "/home/airflow/.local/lib/python3.7/site-packages/urllib3/connection.py", line 187, in _new_conn
    self, "Failed to establish a new connection: %s" % e
urllib3.exceptions.NewConnectionError: <urllib3.connection.HTTPSConnection object at 0x7fbfd28df690>: Failed to establish a new connection: [Errno -3] Temporary failure in name resolution

During handling of the above exception, another exception occurred:

Traceback (most recent call last):
  File "/home/airflow/.local/lib/python3.7/site-packages/requests/adapters.py", line 450, in send
    timeout=timeout
  File "/home/airflow/.local/lib/python3.7/site-packages/urllib3/connectionpool.py", line 786, in urlopen
    method, url, error=e, _pool=self, _stacktrace=sys.exc_info()[2]
  File "/home/airflow/.local/lib/python3.7/site-packages/urllib3/util/retry.py", line 592, in increment
    raise MaxRetryError(_pool, url, error or ResponseError(cause))
urllib3.exceptions.MaxRetryError: HTTPSConnectionPool(host='www.malaysiastock.biz', port=443): Max retries exceeded with url: /Listed-Companies.aspx?type=A&value=0&User-Agent=Mozilla%2F5.0+%28Windows+NT+10.0%3B+Win64%3B+x64%29+AppleWebKit%2F537.36+%28KHTML%2C+like+Gecko%29+Chrome%2F105.0.0.0+Safari%2F537.36 (Caused by NewConnectionError('<urllib3.connection.HTTPSConnection object at 0x7fbfd28df690>: Failed to establish a new connection: [Errno -3] Temporary failure in name resolution'))

During handling of the above exception, another exception occurred:

Traceback (most recent call last):
  File "/home/airflow/.local/lib/python3.7/site-packages/airflow/operators/python.py", line 171, in execute
    return_value = self.execute_callable()
  File "/home/airflow/.local/lib/python3.7/site-packages/airflow/operators/python.py", line 189, in execute_callable
    return self.python_callable(*self.op_args, **self.op_kwargs)
  File "/opt/airflow/dags/web_scraping.py", line 121, in main
    extracted_page = extract(item)
  File "/opt/airflow/dags/web_scraping.py", line 12, in extract
    r = requests.get(url,headers)
  File "/home/airflow/.local/lib/python3.7/site-packages/requests/api.py", line 75, in get
    return request('get', url, params=params, **kwargs)
  File "/home/airflow/.local/lib/python3.7/site-packages/requests/api.py", line 61, in request
    return session.request(method=method, url=url, **kwargs)
  File "/home/airflow/.local/lib/python3.7/site-packages/requests/sessions.py", line 529, in request
    resp = self.send(prep, **send_kwargs)
  File "/home/airflow/.local/lib/python3.7/site-packages/requests/sessions.py", line 645, in send
    r = adapter.send(request, **kwargs)
  File "/home/airflow/.local/lib/python3.7/site-packages/requests/adapters.py", line 519, in send
    raise ConnectionError(e, request=request)
requests.exceptions.ConnectionError: HTTPSConnectionPool(host='www.malaysiastock.biz', port=443): Max retries exceeded with url: /Listed-Companies.aspx?type=A&value=0&User-Agent=Mozilla%2F5.0+%28Windows+NT+10.0%3B+Win64%3B+x64%29+AppleWebKit%2F537.36+%28KHTML%2C+like+Gecko%29+Chrome%2F105.0.0.0+Safari%2F537.36 (Caused by NewConnectionError('<urllib3.connection.HTTPSConnection object at 0x7fbfd28df690>: Failed to establish a new connection: [Errno -3] Temporary failure in name resolution'))
[2022-10-01 20:13:22,451] {taskinstance.py:1400} INFO - Marking task as FAILED. dag_id=main_dag, task_id=web_scraping, execution_date=20221001T201244, start_date=20221001T201248, end_date=20221001T201322
[2022-10-01 20:13:23,092] {standard_task_runner.py:97} ERROR - Failed to execute job 77 for task web_scraping (HTTPSConnectionPool(host='www.malaysiastock.biz', port=443): Max retries exceeded with url: /Listed-Companies.aspx?type=A&value=0&User-Agent=Mozilla%2F5.0+%28Windows+NT+10.0%3B+Win64%3B+x64%29+AppleWebKit%2F537.36+%28KHTML%2C+like+Gecko%29+Chrome%2F105.0.0.0+Safari%2F537.36 (Caused by NewConnectionError('<urllib3.connection.HTTPSConnection object at 0x7fbfd28df690>: Failed to establish a new connection: [Errno -3] Temporary failure in name resolution')); 1356)
[2022-10-01 20:13:26,945] {local_task_job.py:156} INFO - Task exited with return code 1
[2022-10-01 20:13:29,729] {local_task_job.py:273} INFO - 0 downstream tasks scheduled from follow-on schedule check
