[2022-10-01 16:05:34,684] {taskinstance.py:1159} INFO - Dependencies all met for <TaskInstance: main_dag.create_fct_table scheduled__2022-09-30T00:00:00+00:00 [queued]>
[2022-10-01 16:05:34,704] {taskinstance.py:1159} INFO - Dependencies all met for <TaskInstance: main_dag.create_fct_table scheduled__2022-09-30T00:00:00+00:00 [queued]>
[2022-10-01 16:05:34,705] {taskinstance.py:1356} INFO - 
--------------------------------------------------------------------------------
[2022-10-01 16:05:34,707] {taskinstance.py:1357} INFO - Starting attempt 1 of 1
[2022-10-01 16:05:34,711] {taskinstance.py:1358} INFO - 
--------------------------------------------------------------------------------
[2022-10-01 16:05:34,757] {taskinstance.py:1377} INFO - Executing <Task(PostgresOperator): create_fct_table> on 2022-09-30 00:00:00+00:00
[2022-10-01 16:05:34,766] {standard_task_runner.py:52} INFO - Started process 1011 to run task
[2022-10-01 16:05:34,802] {standard_task_runner.py:79} INFO - Running: ['***', 'tasks', 'run', 'main_dag', 'create_fct_table', 'scheduled__2022-09-30T00:00:00+00:00', '--job-id', '8', '--raw', '--subdir', 'DAGS_FOLDER/main_dag.py', '--cfg-path', '/tmp/tmp89b6t1nt', '--error-file', '/tmp/tmpqh1itix1']
[2022-10-01 16:05:34,811] {standard_task_runner.py:80} INFO - Job 8: Subtask create_fct_table
[2022-10-01 16:05:34,964] {task_command.py:369} INFO - Running <TaskInstance: main_dag.create_fct_table scheduled__2022-09-30T00:00:00+00:00 [running]> on host 400f53386831
[2022-10-01 16:05:35,260] {taskinstance.py:1571} INFO - Exporting the following env vars:
AIRFLOW_CTX_DAG_OWNER=***
AIRFLOW_CTX_DAG_ID=main_dag
AIRFLOW_CTX_TASK_ID=create_fct_table
AIRFLOW_CTX_EXECUTION_DATE=2022-09-30T00:00:00+00:00
AIRFLOW_CTX_TRY_NUMBER=1
AIRFLOW_CTX_DAG_RUN_ID=scheduled__2022-09-30T00:00:00+00:00
[2022-10-01 16:05:35,350] {taskinstance.py:1889} ERROR - Task failed with exception
Traceback (most recent call last):
  File "/home/airflow/.local/lib/python3.7/site-packages/airflow/providers/postgres/operators/postgres.py", line 92, in execute
    self.hook.run(self.sql, self.autocommit, parameters=self.parameters)
  File "/home/airflow/.local/lib/python3.7/site-packages/airflow/hooks/dbapi.py", line 181, in run
    with closing(self.get_conn()) as conn:
  File "/home/airflow/.local/lib/python3.7/site-packages/airflow/providers/postgres/hooks/postgres.py", line 86, in get_conn
    conn = deepcopy(self.connection or self.get_connection(conn_id))
  File "/home/airflow/.local/lib/python3.7/site-packages/airflow/hooks/base.py", line 67, in get_connection
    conn = Connection.get_connection_from_secrets(conn_id)
  File "/home/airflow/.local/lib/python3.7/site-packages/airflow/models/connection.py", line 430, in get_connection_from_secrets
    raise AirflowNotFoundException(f"The conn_id `{conn_id}` isn't defined")
airflow.exceptions.AirflowNotFoundException: The conn_id `postgres` isn't defined
[2022-10-01 16:05:35,367] {taskinstance.py:1400} INFO - Marking task as FAILED. dag_id=main_dag, task_id=create_fct_table, execution_date=20220930T000000, start_date=20221001T160534, end_date=20221001T160535
[2022-10-01 16:05:35,510] {standard_task_runner.py:97} ERROR - Failed to execute job 8 for task create_fct_table (The conn_id `postgres` isn't defined; 1011)
[2022-10-01 16:05:35,555] {local_task_job.py:156} INFO - Task exited with return code 1
[2022-10-01 16:05:35,940] {local_task_job.py:273} INFO - 0 downstream tasks scheduled from follow-on schedule check
